Workbook

Sheet Analisis de Mercado
B4: Analisis de Mercado | D4: Observación
B5: Mercado Potencial | C5: 2242 | D5: instituciones publicas y privadas | J5: =C12*(C13*C13)*C14*C15 -> 421.875
B6: Mercado Objetivo | C6: 1846 | D6: Empresa de dotaciones | J6: =((C16*C16)*(C12-1))+((C13*C13)*C14*C15) -> 14.0886
B7: Nicho | C7: 30 | D7: Empresa de dotaciones
B11: Calculo de la Muestra
B12: Tamaño de Población | C12: =C7 -> 30
B13: Nivel de Confianza | C13: 7.5
B14: Probabilidad de Ejecucion | C14: 0.5 | G14: Nivel de Confianza | I14: Error
B15: Probabilidad de No Ejecucion | C15: 0.5 | G15: 0.95 | H15: 7.5 | I15: 0.03
B16: Margen de Error | C16: 0.03 | G16: 0.99 | H16: 9.5 | I16: 0.01
B18: Tamaño de la Muestra | C18: =J5/J6 -> 29.944423

Sheet Estructura de Mercado
B4: Nombre de la Empresa | C4: Asistente
B6: Estructura del Mercado por Unidades
B7: Producto | C7: Clientes Potenciales | D7: Habitos de Consumo Cliente | E7: Ventas Mensuales | F7: Participacion en el Mercado | G7: Ventas Anuales
B8: Asistnte | C8: ='Analisis de Mercado'!C7 -> 30 | D8: 1 | E8: 1 | F8: =G8/(C8*D8) -> 0.4 | G8: =E8*12 -> 12
B12: Totales | C12: =SUM(C8:C11) -> 30 | D12: =SUM(D8:D11) -> 1 | E12: =SUM(E8:E11) -> 1 | F12: =SUM(F8:F11) -> 0.4 | G12: =SUM(G8:G11) -> 12

Sheet Datos Economicos
C4: Ventas Anules por Producto
C5: Producto | D5: Unidades a Vender en el Año | E5: Precio Unitario | F5: Ventas Totales año 1
C6: ='Estructura de Mercado'!B8 -> Asistnte | D6: 22 | E6: 2000000 | F6: =E6*D6 -> 44000000
C7: ='Estructura de Mercado'!B9 -> 0 | D7: ='Estructura de Mercado'!G9 -> 0 | F7: =E7*D7 -> 0
C8: ='Estructura de Mercado'!B10 -> 0 | D8: ='Estructura de Mercado'!G10 -> 0 | F8: =E8*D8 -> 0
C9: ='Estructura de Mercado'!B11 -> 0 | D9: ='Estructura de Mercado'!G11 -> 0 | F9: =E9*D9 -> 0
C16: Datos Economicos
C17: Indicadores | D17: Año 1 | E17: Año 2 | F17: Año 3 | G17: Año 4 | H17: Año 5
C18: Inflación | D18: 0.035 | E18: 0.037 | F18: 0.031 | G18: 0.037 | H18: 0.031
C19: D.T.F | D19: 0.0229 | E19: 0.0316 | F19: 0.0405 | G19: 0.0463 | H19: 0.0514
C20: I.P.C | D20: 0.035 | E20: 0.035 | F20: 0.037 | G20: 0.032 | H20: 0.031
C21: I.P.P | D21: 0.035 | E21: 0.035 | F21: 0.037 | G21: 0.032 | H21: 0.031
C22: P.I.B | D22: 0.036 | E22: 0.034 | F22: 0.032 | G22: 0.032 | H22: 0.031

Sheet ParaFiscales
B3: Nomina
B4: Salario Minimo | C4: 1423000
B5: Auxilio de Transporte | C5: 200000
B6: Salario Minimo Integral | C6: 18505500
B7: Aportes Fiscales
B8: SENA | C8: 0.02
B9: ICBF | C9: 0.03
B10: Cajas | C10: 0.04
B11: Total | C11: =SUM(C8:C10) -> 0.09
B12: Cargas Prestacionales
B13: Cesantias | C13: 0.0833
B14: Intereses a las Cesantias | C14: 0.01
B15: Prima de Servicios | C15: 0.0833
B16: Vacaciones | C16: 0.0417
B17: Total | C17: =SUM(C13:C16) -> 0.2183
B18: Seguridad Social
B19: Salud
B20: Empresa | C20: 0.085
B21: Empleado | C21: 0.04
B22: Pension
B23: Empresa | C23: 0.12
B24: Empleado | C24: 0.04
B25: Total Empresa | C25: =SUM(C20+C23) -> 0.205
B26: Total Empleado | C26: =SUM(C21+C24) -> 0.08
B27: Totales | C27: =SUM(C11+C17+C25) -> 0.5133

Sheet Gastos de Constitución
B4: Registro Mercantil
B5: Concepto | C5: Unidad | D5: Valor | E5: Total
E6: =C6*D6 -> 0
E7: =C7*D7 -> 0
E8: =C8*D8 -> 0
E9: =C9*D9 -> 0
E10: =C10*D10 -> 0
B11: Total | D11: =SUM(D6:D10) -> 0 | E11: =SUM(E6:E10) -> 0
B14: Permisos y Licencias
B15: Concepto | C15: Unidad | D15: Valor | E15: Total
E16: =C16*D16 -> 0
E17: =C17*D17 -> 0
E18: =C18*D18 -> 0
E19: =C19*D19 -> 0
E20: =C20*D20 -> 0
B21: Total | D21: =SUM(D16:D20) -> 0 | E21: =SUM(E16:E20) -> 0

Sheet Plan de Inversion
B3: Activos Fijos | H3: Plan de Inversion | K3: Depreciaciones
B4: Descripcion | C4: Unidad Medida | D4: Cantidad | E4: Valor Unitario | F4: Total | H4: Activos Fijos | I4: =F9 -> 0 | K4: Concepto | L4: Valor total | M4: Vida Util | N4: Año 1 | O4: Año 2 | P4: Año 3 | Q4: Año 4 | R4: Año 5
F5: =D5*E5 -> 0 | H5: Adecuaciones | I5: =F18 -> 0 | K5: Adecuaciones | L5: =I5 -> 0 | M5: 20 | N5: =$L$5/$M$5 -> 0 | O5: =$L$5/$M$5 -> 0 | P5: =$L$5/$M$5 -> 0 | Q5: =$L$5/$M$5 -> 0 | R5: =$L$5/$M$5 -> 0
F6: =D6*E6 -> 0 | H6: Muebles y Enseres | I6: =F35 -> 1520232 | K6: Muebles y Enseres | L6: =I6 -> 1520232 | M6: 10 | N6: =$L$6/$M$6 -> 152023.2 | O6: =$L$6/$M$6 -> 152023.2 | P6: =$L$6/$M$6 -> 152023.2 | Q6: =$L$6/$M$6 -> 152023.2 | R6: =$L$6/$M$6 -> 152023.2
F7: =D7*E7 -> 0 | H7: Maquinaria y Equipo | I7: =F52 -> 6500000 | K7: Maquinaria y Equipo | L7: =I7 -> 6500000 | M7: 5 | N7: =$L$7/$M$7 -> 1300000 | O7: =$L$7/$M$7 -> 1300000 | P7: =$L$7/$M$7 -> 1300000 | Q7: =$L$7/$M$7 -> 1300000 | R7: =$L$7/$M$7 -> 1300000
F8: =D8*E8 -> 0 | H8: Total | I8: =SUM(I4:I7) -> 8020232 | K8: Total | L8: =SUM(L4:L7) -> 8020232 | N8: =SUM(N5:N7) -> 1452023.2 | O8: =SUM(O5:O7) -> 1452023.2 | P8: =SUM(P5:P7) -> 1452023.2 | Q8: =SUM(Q5:Q7) -> 1452023.2 | R8: =SUM(R5:R7) -> 1452023.2
B9: Total | F9: =SUM(F5:F8) -> 0
B12: Adecuaciones
B13: Descripcion | C13: Unidad Medida | D13: Cantidad | E13: Valor Unitario | F13: Total
F14: =D14*E14 -> 0
F15: =(D15*E15) -> 0
F16: =(D16*E16) -> 0
F17: =(D17*E17) -> 0
B18: Total | F18: =SUM(F14:F17) -> 0
B21: Muebles y Enseres
B22: Descripcion | C22: Unidad Medida | D22: Cantidad | E22: Valor Unitario | F22: Total
B23: Silla Para Oficina Ergonomica | C23: Unidad | D23: 3 | E23: 138900 | F23: =D23*E23 -> 416700
B24: Escritorio en L | C24: Unidad | D24: 3 | E24: 367844 | F24: =D24*E24 -> 1103532
F25: =D25*E25 -> 0
F26: =D26*E26 -> 0
F27: =D27*E27 -> 0
F28: =D28*E28 -> 0
F29: =D29*E29 -> 0
F30: =D30*E30 -> 0
F31: =D31*E31 -> 0
F32: =(D32*E32) -> 0
F33: =(D33*E33) -> 0
F34: =(D34*E34) -> 0
B35: Total | F35: =SUM(F23:F34) -> 1520232
B38: Maquinaria y Equipo
B39: Descripcion | C39: Unidad Medida | D39: Cantidad | E39: Valor Unitario | F39: Total
B40: Computador Escritorio | C40: Unidad | D40: 2 | E40: 2000000 | F40: =D40*E40 -> 4000000
B41: Portatil HP | C41: Unidad | D41: 1 | E41: 2500000 | F41: =D41*E41 -> 2500000
F42: =D42*E42 -> 0
F43: =D43*E43 -> 0
F44: =D44*E44 -> 0
F45: =D45*E45 -> 0
F46: =D46*E46 -> 0
F47: =D47*E47 -> 0
F48: =D48*E48 -> 0
...

Sheet Gastos de Personal
B3: Requerimiento de Personal | E3: Salud | H3: Pension | K3: Subsidio de Transporte | L3: Total a Pagar | M3: Sueldo Total Año
B4: Cargo | C4: Sueldo Mensual | D4: Dias Laborados | E4: Empleado | F4: Empresa | G4: Total | H4: Empleado | I4: Empresa | J4: Total | K4: Empleado | L4: Total
B5: Director Tecnico | C5: 1800000 | D5: 30 | E5: =C5*ParaFiscales!$C$21 -> 72000 | F5: =C5*ParaFiscales!$C$20 -> 153000 | G5: =SUM(E5:F5) -> 225000 | H5: =C5*ParaFiscales!$C$24 -> 72000 | I5: =C5*ParaFiscales!$C$23 -> 216000 | J5: =SUM(H5:I5) -> 288000 | K5: 200000 | L5: =(C5-E5-H5+K5) -> 1856000 | M5: =C5*12 -> 21600000
B6: Ditector Administrativo | C6: 1800000 | D6: 30 | E6: =C6*ParaFiscales!$C$21 -> 72000 | F6: =C6*ParaFiscales!$C$20 -> 153000 | G6: =SUM(E6:F6) -> 225000 | H6: =C6*ParaFiscales!$C$24 -> 72000 | I6: =C6*ParaFiscales!$C$23 -> 216000 | J6: =SUM(H6:I6) -> 288000 | K6: 200000 | L6: =(C6-E6-H6+K6) -> 1856000 | M6: =C6*12 -> 21600000
B7: Programador Junior | C7: 1600000 | D7: 30 | E7: =C7*ParaFiscales!$C$21 -> 64000 | F7: =C7*ParaFiscales!$C$20 -> 136000 | G7: =SUM(E7:F7) -> 200000 | H7: =C7*ParaFiscales!$C$24 -> 64000 | I7: =C7*ParaFiscales!$C$23 -> 192000 | J7: =SUM(H7:I7) -> 256000 | K7: 200000 | L7: =(C7-E7-H7+K7) -> 1672000 | M7: =C7*12 -> 19200000
C8: 1800000 | D8: 30 | E8: =C8*ParaFiscales!$C$21 -> 72000 | F8: =C8*ParaFiscales!$C$20 -> 153000 | G8: =SUM(E8:F8) -> 225000 | H8: =C8*ParaFiscales!$C$24 -> 72000 | I8: =C8*ParaFiscales!$C$23 -> 216000 | J8: =SUM(H8:I8) -> 288000 | L8: =(C8-E8-H8+K8) -> 1656000 | M8: =C8*12 -> 21600000
E9: =C9*ParaFiscales!$C$21 -> 0 | F9: =C9*ParaFiscales!$C$20 -> 0 | G9: =SUM(E9:F9) -> 0 | H9: =C9*ParaFiscales!$C$24 -> 0 | I9: =C9*ParaFiscales!$C$23 -> 0 | J9: =SUM(H9:I9) -> 0 | L9: =(C9-E9-H9+K9) -> 0 | M9: =C9*12 -> 0
E10: =C10*ParaFiscales!$C$21 -> 0 | F10: =C10*ParaFiscales!$C$20 -> 0 | G10: =SUM(E10:F10) -> 0 | H10: =C10*ParaFiscales!$C$24 -> 0 | I10: =C10*ParaFiscales!$C$23 -> 0 | J10: =SUM(H10:I10) -> 0 | L10: =(C10-E10-H10+K10) -> 0 | M10: =C10*12 -> 0
E11: =C11*ParaFiscales!$C$21 -> 0 | F11: =C11*ParaFiscales!$C$20 -> 0 | G11: =SUM(E11:F11) -> 0 | H11: =C11*ParaFiscales!$C$24 -> 0 | I11: =C11*ParaFiscales!$C$23 -> 0 | J11: =SUM(H11:I11) -> 0 | L11: =(C11-E11-H11+K11) -> 0 | M11: =C11*12 -> 0
E12: =C12*ParaFiscales!$C$21 -> 0 | F12: =C12*ParaFiscales!$C$20 -> 0 | G12: =SUM(E12:F12) -> 0 | H12: =C12*ParaFiscales!$C$24 -> 0 | I12: =C12*ParaFiscales!$C$23 -> 0 | J12: =SUM(H12:I12) -> 0 | L12: =(C12-E12-H12+K12) -> 0 | M12: =C12*12 -> 0
E13: =C13*ParaFiscales!$C$21 -> 0 | F13: =C13*ParaFiscales!$C$20 -> 0 | G13: =SUM(E13:F13) -> 0 | H13: =C13*ParaFiscales!$C$24 -> 0 | I13: =C13*ParaFiscales!$C$23 -> 0 | J13: =SUM(H13:I13) -> 0 | L13: =(C13-E13-H13+K13) -> 0 | M13: =C13*12 -> 0
E14: =C14*ParaFiscales!$C$21 -> 0 | F14: =C14*ParaFiscales!$C$20 -> 0 | G14: =SUM(E14:F14) -> 0 | H14: =C14*ParaFiscales!$C$24 -> 0 | I14: =C14*ParaFiscales!$C$23 -> 0 | J14: =SUM(H14:I14) -> 0 | L14: =(C14-E14-H14+K14) -> 0 | M14: =C14*12 -> 0
E15: =C15*ParaFiscales!$C$21 -> 0 | F15: =C15*ParaFiscales!$C$20 -> 0 | G15: =SUM(E15:F15) -> 0 | H15: =C15*ParaFiscales!$C$24 -> 0 | I15: =C15*ParaFiscales!$C$23 -> 0 | J15: =SUM(H15:I15) -> 0 | L15: =(C15-E15-H15+K15) -> 0 | M15: =C15*12 -> 0
E16: =C16*ParaFiscales!$C$21 -> 0 | F16: =C16*ParaFiscales!$C$20 -> 0 | G16: =SUM(E16:F16) -> 0 | H16: =C16*ParaFiscales!$C$24 -> 0 | I16: =C16*ParaFiscales!$C$23 -> 0 | J16: =SUM(H16:I16) -> 0 | L16: =(C16-E16-H16+K16) -> 0 | M16: =C16*12 -> 0
B17: Totales | C17: =SUM(C5:C16) -> 7000000 | E17: =SUM(E5:E16) -> 280000 | F17: =SUM(F5:F16) -> 595000 | G17: =SUM(G5:G16) -> 875000 | H17: =SUM(H5:H16) -> 280000 | I17: =SUM(I5:I16) -> 840000 | J17: =SUM(J5:J16) -> 1120000 | K17: =SUM(K5:K16) -> 600000 | L17: =SUM(L5:L16) -> 7040000 | M17: =SUM(M5:M16) -> 84000000
E19: Primer Año
B20: Aportes Fiscales | E20: Sueldo | F20: Aportes Fiscales | G20: Carga Prestacional | H20: Seguridad Social
B21: SENA | C21: =$C$17*ParaFiscales!C8 -> 140000 | E21: =C17*12 -> 84000000 | F21: =C24*12 -> 7560000 | G21: =C30*12 -> 18337200 | H21: =(C33+C35)*12 -> 17220000
B22: ICBF | C22: =$C$17*ParaFiscales!C9 -> 210000
B23: Cajas | C23: =$C$17*ParaFiscales!C10 -> 280000
B24: Total | C24: =SUM(C21:C23) -> 630000 | E24: Gastos de Personal Anualizado | L24: Parafiscales
B25: Cargas Prestacionales | E25: Cargo | F25: Año 1 | G25: Año 2 | H25: Año 3 | I25: Año 4 | J25: Año 5 | L25: Cargo | M25: Año 1 | N25: Año 2 | O25: Año 3 | P25: Año 4 | Q25: Año 5
B26: Cesantias | C26: =$C$17*ParaFiscales!C13 -> 583100 | E26: =B5 -> Director Tecnico | F26: =M5 -> 21600000 | G26: =(F26*'Datos Economicos'!D20)+F26 -> 22356000 | H26: =(G26*'Datos Economicos'!E20)+G26 -> 23138460 | I26: =(H26*'Datos Economicos'!F20)+H26 -> 23994583 | J26: =(I26*'Datos Economicos'!G20)+I26 -> 24762410 | L26: =B21 -> SENA | M26: =C21 -> 140000 | N26: =(M26*'Datos Economicos'!$D$20)+M26 -> 144900 | O26: =(N26*'Datos Economicos'!$D$20)+N26 -> 149971.5 | P26: =(O26*'Datos Economicos'!$D$20)+O26 -> 155220.5 | Q26: =(P26*'Datos Economicos'!$D$20)+P26 -> 160653.22
B27: Intereses a las Cesantias | C27: =$C$17*ParaFiscales!C14 -> 70000 | E27: =B6 -> Ditector Administrativo | F27: =M6 -> 21600000 | G27: =(F27*'Datos Economicos'!D20)+F27 -> 22356000 | H27: =(G27*'Datos Economicos'!E20)+G27 -> 23138460 | I27: =(H27*'Datos Economicos'!D20)+H27 -> 23948306 | J27: =(I27*'Datos Economicos'!D20)+I27 -> 24786497 | L27: =B22 -> ICBF | M27: =C22 -> 210000 | N27: =(M27*'Datos Economicos'!$D$20)+M27 -> 217350 | O27: =(N27*'Datos Economicos'!$D$20)+N27 -> 224957.25 | P27: =(O27*'Datos Economicos'!$D$20)+O27 -> 232830.75 | Q27: =(P27*'Datos Economicos'!$D$20)+P27 -> 240979.83
B28: Prima de Servicios | C28: =$C$17*ParaFiscales!C15 -> 583100 | E28: =B7 -> Programador Junior | F28: =M7 -> 19200000 | G28: =(F28*'Datos Economicos'!D22)+F28 -> 19891200 | H28: =(F28*'Datos Economicos'!E22)+F28 -> 19852800 | I28: =(F28*'Datos Economicos'!F22)+F28 -> 19814400 | J28: =(F28*'Datos Economicos'!G22)+F28 -> 19814400 | L28: =B23 -> Cajas | M28: =C23 -> 280000 | N28: =(M28*'Datos Economicos'!$D$20)+M28 -> 289800 | O28: =(N28*'Datos Economicos'!$D$20)+N28 -> 299943 | P28: =(O28*'Datos Economicos'!$D$20)+O28 -> 310441.01 | Q28: =(P28*'Datos Economicos'!$D$20)+P28 -> 321306.44
B29: Vacaciones | C29: =$C$17*ParaFiscales!C16 -> 291900 | E29: =B8 -> 0 | F29: =M8 -> 21600000 | G29: =(F29*'Datos Economicos'!D23)+F29 -> 21600000 | H29: =(F29*'Datos Economicos'!E23)+F29 -> 21600000 | I29: =(F29*'Datos Economicos'!F23)+F29 -> 21600000 | J29: =(F29*'Datos Economicos'!G23)+F29 -> 21600000 | L29: =B26 -> Cesantias | M29: =C26 -> 583100 | N29: =(M29*'Datos Economicos'!$D$20)+M29 -> 603508.5 | O29: =(N29*'Datos Economicos'!$D$20)+N29 -> 624631.3 | P29: =(O29*'Datos Economicos'!$D$20)+O29 -> 646493.39 | Q29: =(P29*'Datos Economicos'!$D$20)+P29 -> 669120.66
B30: Total | C30: =SUM(C26:C29) -> 1528100 | F30: =M9 -> 0 | G30: =(F30*'Datos Economicos'!D24)+F30 -> 0 | H30: =(F30*'Datos Economicos'!E24)+F30 -> 0 | I30: =(F30*'Datos Economicos'!F24)+F30 -> 0 | J30: =(F30*'Datos Economicos'!G24)+F30 -> 0 | L30: =B27 -> Intereses a las Cesantias | M30: =C27 -> 70000 | N30: =(M30*'Datos Economicos'!$D$20)+M30 -> 72450 | O30: =(N30*'Datos Economicos'!$D$20)+N30 -> 74985.75 | P30: =(O30*'Datos Economicos'!$D$20)+O30 -> 77610.251 | Q30: =(P30*'Datos Economicos'!$D$20)+P30 -> 80326.61
B31: Seguridad Social | F31: =M10 -> 0 | G31: =(F31*'Datos Economicos'!D25)+F31 -> 0 | H31: =(F31*'Datos Economicos'!E25)+F31 -> 0 | I31: =(F31*'Datos Economicos'!F25)+F31 -> 0 | J31: =(F31*'Datos Economicos'!G25)+F31 -> 0 | L31: =B28 -> Prima de Servicios | M31: =C28 -> 583100 | N31: =(M31*'Datos Economicos'!$D$20)+M31 -> 603508.5 | O31: =(N31*'Datos Economicos'!$D$20)+N31 -> 624631.3 | P31: =(O31*'Datos Economicos'!$D$20)+O31 -> 646493.39 | Q31: =(P31*'Datos Economicos'!$D$20)+P31 -> 669120.66
B32: Salud | F32: =M11 -> 0 | G32: =(F32*'Datos Economicos'!D26)+F32 -> 0 | H32: =(F32*'Datos Economicos'!E26)+F32 -> 0 | I32: =(F32*'Datos Economicos'!F26)+F32 -> 0 | J32: =(F32*'Datos Economicos'!G26)+F32 -> 0 | L32: =B29 -> Vacaciones | M32: =C29 -> 291900 | N32: =(M32*'Datos Economicos'!$D$20)+M32 -> 302116.5 | O32: =(N32*'Datos Economicos'!$D$20)+N32 -> 312690.58 | P32: =(O32*'Datos Economicos'!$D$20)+O32 -> 323634.75 | Q32: =(P32*'Datos Economicos'!$D$20)+P32 -> 334961.96
B33: Empresa | C33: =C17*ParaFiscales!C20 -> 595000 | F33: =M12 -> 0 | G33: =(F33*'Datos Economicos'!D27)+F33 -> 0 | H33: =(F33*'Datos Economicos'!E27)+F33 -> 0 | I33: =(F33*'Datos Economicos'!F27)+F33 -> 0 | J33: =(F33*'Datos Economicos'!G27)+F33 -> 0 | L33: =B32 -> Salud | M33: =C33 -> 595000 | N33: =(M33*'Datos Economicos'!$D$20)+M33 -> 615825 | O33: =(N33*'Datos Economicos'!$D$20)+N33 -> 637378.88 | P33: =(O33*'Datos Economicos'!$D$20)+O33 -> 659687.14 | Q33: =(P33*'Datos Economicos'!$D$20)+P33 -> 682776.19
B34: Pension | F34: =M13 -> 0 | G34: =(F34*'Datos Economicos'!D28)+F34 -> 0 | H34: =(F34*'Datos Economicos'!E28)+F34 -> 0 | I34: =(F34*'Datos Economicos'!F28)+F34 -> 0 | J34: =(F34*'Datos Economicos'!G28)+F34 -> 0 | L34: =B34 -> Pension | M34: =C35 -> 840000 | N34: =(M34*'Datos Economicos'!$D$20)+M34 -> 869400 | O34: =(N34*'Datos Economicos'!$D$20)+N34 -> 899829 | P34: =(O34*'Datos Economicos'!$D$20)+O34 -> 931323.02 | Q34: =(P34*'Datos Economicos'!$D$20)+P34 -> 963919.32
B35: Empresa | C35: =C17*ParaFiscales!C23 -> 840000 | F35: =M14 -> 0 | G35: =(F35*'Datos Economicos'!D29)+F35 -> 0 | H35: =(F35*'Datos Economicos'!E29)+F35 -> 0 | I35: =(F35*'Datos Economicos'!F29)+F35 -> 0 | J35: =(F35*'Datos Economicos'!G29)+F35 -> 0 | M35: =T14 -> 0 | N35: =(M35*'Datos Economicos'!K29)+M35 -> 0 | O35: =(M35*'Datos Economicos'!L29)+M35 -> 0 | P35: =(M35*'Datos Economicos'!M29)+M35 -> 0 | Q35: =(M35*'Datos Economicos'!N29)+M35 -> 0
B36: Totales | C36: =SUM(C24+C30+C33+C35) -> 3593100 | F36: =M15 -> 0 | G36: =(F36*'Datos Economicos'!D30)+F36 -> 0 | H36: =(F36*'Datos Economicos'!E30)+F36 -> 0 | I36: =(F36*'Datos Economicos'!F30)+F36 -> 0 | J36: =(F36*'Datos Economicos'!G30)+F36 -> 0 | M36: =T15 -> 0 | N36: =(M36*'Datos Economicos'!K30)+M36 -> 0 | O36: =(M36*'Datos Economicos'!L30)+M36 -> 0 | P36: =(M36*'Datos Economicos'!M30)+M36 -> 0 | Q36: =(M36*'Datos Economicos'!N30)+M36 -> 0
E37: Total | F37: =SUM(F26:F36) -> 84000000 | G37: =SUM(G26:G36) -> 86203200 | H37: =SUM(H26:H36) -> 87729720 | I37: =SUM(I26:I36) -> 89357289 | J37: =SUM(J26:J36) -> 90963306 | L37: Total | M37: =SUM(M26:M36) -> 3593100 | N37: =SUM(N26:N36) -> 3718858.5 | O37: =SUM(O26:O36) -> 3849018.5 | P37: =SUM(P26:P36) -> 3983734.2 | Q37: =SUM(Q26:Q36) -> 4123164.9

Sheet Gastos Administrativos
C3: Gastos Administrativos
C4: Concepto | D4: Valor | E4: Mes 1 | F4: Total Año
C5: Arrendamiento | D5: 800000 | E5: =D5 -> 800000 | F5: =E5*12 -> 9600000
C6: Servicios Publicos | D6: 200000 | E6: =D6 -> 200000 | F6: =E6*12 -> 2400000
C7: Suministros de Oficina | D7: 80000 | E7: =D7 -> 80000 | F7: =E7*12 -> 960000
C8: Aseo e Higiene | D8: 50000 | E8: =D8 -> 50000 | F8: =E8*12 -> 600000
C9: Telefonia | D9: 90000 | E9: =D9 -> 90000 | F9: =E9*12 -> 1080000
C10: Internet | D10: 120000 | E10: =D10 -> 120000 | F10: =E10*12 -> 1440000
E11: =D11 -> 0 | F11: =E11*12 -> 0
E12: =D12 -> 0 | F12: =E12*12 -> 0
E13: =D13 -> 0 | F13: =E13*12 -> 0
E14: =D14 -> 0 | F14: =E14*12 -> 0
E15: =D15 -> 0 | F15: =E15*12 -> 0
C16: Total | D16: =SUM(D5:D15) -> 1340000 | E16: =SUM(E5:E15) -> 1340000 | F16: =SUM(F5:F15) -> 16080000
C18: Gastos de Administración
C19: Concepto | D19: Año 1 | E19: Año 2 | F19: Año 3 | G19: Año 4 | H19: Año 5
C20: =C5 -> Arrendamiento | D20: =F5 -> 9600000 | E20: =(D20*'Datos Economicos'!$E$20)+D20 -> 9936000 | F20: =(E20*'Datos Economicos'!$F$20)+E20 -> 10303632 | G20: =(F20*'Datos Economicos'!$G$20)+F20 -> 10633348 | H20: =(G20*'Datos Economicos'!$H$20)+G20 -> 10962982
C21: =C6 -> Servicios Publicos | D21: =F6 -> 2400000 | E21: =(D21*'Datos Economicos'!$E$20)+D21 -> 2484000 | F21: =(E21*'Datos Economicos'!$F$20)+E21 -> 2575908 | G21: =(F21*'Datos Economicos'!$G$20)+F21 -> 2658337.1 | H21: =(G21*'Datos Economicos'!$H$20)+G21 -> 2740745.5
C22: =C7 -> Suministros de Oficina | D22: =F7 -> 960000 | E22: =(D22*'Datos Economicos'!$E$20)+D22 -> 993600 | F22: =(E22*'Datos Economicos'!$F$20)+E22 -> 1030363.2 | G22: =(F22*'Datos Economicos'!$G$20)+F22 -> 1063334.8 | H22: =(G22*'Datos Economicos'!$H$20)+G22 -> 1096298.2
C23: =C8 -> Aseo e Higiene | D23: =F8 -> 600000 | E23: =(D23*'Datos Economicos'!$E$20)+D23 -> 621000 | F23: =(E23*'Datos Economicos'!$F$20)+E23 -> 643977 | G23: =(F23*'Datos Economicos'!$G$20)+F23 -> 664584.26 | H23: =(G23*'Datos Economicos'!$H$20)+G23 -> 685186.38
C24: =C9 -> Telefonia | D24: =F9 -> 1080000 | E24: =(D24*'Datos Economicos'!$E$20)+D24 -> 1117800 | F24: =(E24*'Datos Economicos'!$F$20)+E24 -> 1159158.6 | G24: =(F24*'Datos Economicos'!$G$20)+F24 -> 1196251.7 | H24: =(G24*'Datos Economicos'!$H$20)+G24 -> 1233335.5
C25: =C10 -> Internet | D25: =F10 -> 1440000 | E25: =(D25*'Datos Economicos'!$E$20)+D25 -> 1490400 | F25: =(E25*'Datos Economicos'!$F$20)+E25 -> 1545544.8 | G25: =(F25*'Datos Economicos'!$G$20)+F25 -> 1595002.2 | H25: =(G25*'Datos Economicos'!$H$20)+G25 -> 1644447.3
C26: =C11 -> 0 | D26: =F11 -> 0 | E26: =(D26*'Datos Economicos'!$E$20)+D26 -> 0 | F26: =(E26*'Datos Economicos'!$F$20)+E26 -> 0 | G26: =(F26*'Datos Economicos'!$G$20)+F26 -> 0 | H26: =(G26*'Datos Economicos'!$H$20)+G26 -> 0
C31: Total | D31: =SUM(D20:D30) -> 16080000 | E31: =SUM(E20:E30) -> 16642800 | F31: =SUM(F20:F30) -> 17258584 | G31: =SUM(G20:G30) -> 17810858 | H31: =SUM(H20:H30) -> 18362995

Sheet Gastos de Marketing
C3: Gastos Administrativos
C4: Concepto | D4: Valor | E4: Mes 1 | F4: Total Año
E5: =D5 -> 0 | F5: =E5*12 -> 0
E6: =D6 -> 0 | F6: =E6*12 -> 0
E7: =D7 -> 0 | F7: =E7*12 -> 0
E8: =D8 -> 0 | F8: =E8*12 -> 0
E9: =D9 -> 0 | F9: =E9*12 -> 0
E10: =D10 -> 0 | F10: =E10*12 -> 0
E11: =D11 -> 0 | F11: =E11*12 -> 0
E12: =D12 -> 0 | F12: =E12*12 -> 0
E13: =D13 -> 0 | F13: =E13*12 -> 0
E14: =D14 -> 0 | F14: =E14*12 -> 0
E15: =D15 -> 0 | F15: =E15*12 -> 0
C16: Total | D16: =SUM(D5:D15) -> 0 | E16: =SUM(E5:E15) -> 0 | F16: =SUM(F5:F15) -> 0
C18: Gastos de Ventas
C19: Concepto | D19: Año 1 | E19: Año 2 | F19: Año 3 | G19: Año 4 | H19: Año 5
C20: =C5 -> 0 | D20: =F5 -> 0 | E20: =(D20*'Datos Economicos'!$E$20)+D20 -> 0 | F20: =(E20*'Datos Economicos'!$F$20)+E20 -> 0 | G20: =(F20*'Datos Economicos'!$G$20)+F20 -> 0 | H20: =(G20*'Datos Economicos'!$H$20)+G20 -> 0
C21: =C6 -> 0 | D21: =F6 -> 0 | E21: =(D21*'Datos Economicos'!$E$20)+D21 -> 0 | F21: =(E21*'Datos Economicos'!$F$20)+E21 -> 0 | G21: =(F21*'Datos Economicos'!$G$20)+F21 -> 0 | H21: =(G21*'Datos Economicos'!$H$20)+G21 -> 0
C22: =C7 -> 0 | D22: =F7 -> 0 | E22: =(D22*'Datos Economicos'!$E$20)+D22 -> 0 | F22: =(E22*'Datos Economicos'!$F$20)+E22 -> 0 | G22: =(F22*'Datos Economicos'!$G$20)+F22 -> 0 | H22: =(G22*'Datos Economicos'!$H$20)+G22 -> 0
C31: Total | D31: =SUM(D20:D30) -> 0 | E31: =SUM(E20:E30) -> 0 | F31: =SUM(F20:F30) -> 0 | G31: =SUM(G20:G30) -> 0 | H31: =SUM(H20:H30) -> 0

Sheet Producto 1
B2: Producto | C2: ='Estructura de Mercado'!B8 -> Asistnte
B4: Costo Unitario Total
B5: Concepto | C5: Costo Unitario Año Base | D5: Año 1 | E5: Año 2 | F5: Año 3 | G5: Año 4 | H5: Año 5
B6: Materia Prima e Insumos | C6: =F28 -> 0 | D6: =C6 -> 0 | E6: =(D6*'Datos Economicos'!E21)+D6 -> 0 | F6: =(E6*'Datos Economicos'!F21)+E6 -> 0 | G6: =(F6*'Datos Economicos'!G21)+F6 -> 0 | H6: =(G6*'Datos Economicos'!H21)+G6 -> 0
B10: Total | C10: =SUM(C6:C9) -> 0 | D10: =SUM(D6:D9) -> 0 | E10: =SUM(E6:E9) -> 0 | F10: =SUM(F6:F9) -> 0 | G10: =SUM(G6:G9) -> 0 | H10: =SUM(H6:H9) -> 0
B13: Insumos
B14: Materia Prima | C14: Unidad de Medida | D14: Valor Unitario | E14: Cantidad Por unidad | F14: Total Costo Unitario
B15: MariaDb | C15: Unidad de Medida | D15: 0 | E15: 1 | F15: =D15*E15 -> 0
B16: Xammpp | C16: Unidad de Medida | D16: 0 | E16: 1 | F16: =D16*E16 -> 0
B17: Draw.io | C17: Unidad de Medida | D17: 0 | E17: 1 | F17: =D17*E17 -> 0
B18: visual studio | C18: Unidad de Medida | D18: 0 | E18: 1 | F18: =D18*E18 -> 0
B19: React | C19: Unidad de Medida | D19: 0 | E19: 1 | F19: =D19*E19 -> 0
B20: Androdi Studio | C20: Unidad de Medida | D20: 0 | E20: 1 | F20: =D20*E20 -> 0
D21: 0 | F21: =D21*E21 -> 0
D22: 0 | F22: =D22*E22 -> 0
D23: 0 | F23: =D23*E23 -> 0
D24: 0 | F24: =D24*E24 -> 0
D25: 0 | F25: =D25*E25 -> 0
D26: 0 | F26: =D26*E26 -> 0
D27: 0 | F27: =D27*E27 -> 0
B28: Sub Total | D28: =SUM(D15:D27) -> 0 | F28: =SUM(F15:F27) -> 0
B31: Mano de Obra
B32: Mano de Obra | C32: Unidad de Medida | D32: Valor Unitario | E32: Cantidad Por unidad | F32: Total Costo Unitario
B46: Sub Total | D46: =SUM(D33:D45) -> 0 | F46: =SUM(F33:F45) -> 0

Sheet Producto 2
B2: Producto
B4: Costo Unitario Total
B5: Concepto | C5: Costo Unitario Año Base | D5: Año 1 | E5: Año 2 | F5: Año 3 | G5: Año 4 | H5: Año 5
B6: Materia Prima e Insumos
B10: Total | C10: =SUM(C6:C9) -> 0 | D10: =SUM(D6:D9) -> 0 | E10: =SUM(E6:E9) -> 0 | F10: =SUM(F6:F9) -> 0 | G10: =SUM(G6:G9) -> 0 | H10: =SUM(H6:H9) -> 0
B13: Insumos
B14: Materia Prima | C14: Unidad de Medida | D14: Valor Unitario | E14: Cantidad Por unidad | F14: Total Costo Unitario
F15: =D15*E15 -> 0
F16: =D16*E16 -> 0
B28: Sub Total | D28: =SUM(D15:D27) -> 0 | F28: =SUM(F15:F27) -> 0
B31: Mano de Obra
B32: Mano de Obra | C32: Unidad de Medida | D32: Valor Unitario | E32: Cantidad Por unidad | F32: Total Costo Unitario
B46: Sub Total | D46: =SUM(D33:D45) -> 0 | F46: =SUM(F33:F45) -> 0

Sheet Producto 3
B2: Producto
B4: Costo Unitario Total
B5: Concepto | C5: Costo Unitario Año Base | D5: Año 1 | E5: Año 2 | F5: Año 3 | G5: Año 4 | H5: Año 5
B6: Materia Prima e Insumos
B10: Total | C10: =SUM(C6:C9) -> 0 | D10: =SUM(D6:D9) -> 0 | E10: =SUM(E6:E9) -> 0 | F10: =SUM(F6:F9) -> 0 | G10: =SUM(G6:G9) -> 0 | H10: =SUM(H6:H9) -> 0
B13: Insumos
B14: Materia Prima | C14: Unidad de Medida | D14: Valor Unitario | E14: Cantidad Por unidad | F14: Total Costo Unitario
F15: =D15*E15 -> 0
F16: =D16*E16 -> 0
B28: Sub Total | D28: =SUM(D15:D27) -> 0 | F28: =SUM(F15:F27) -> 0
B31: Mano de Obra
B32: Mano de Obra | C32: Unidad de Medida | D32: Valor Unitario | E32: Cantidad Por unidad | F32: Total Costo Unitario
B46: Sub Total | D46: =SUM(D33:D45) -> 0 | F46: =SUM(F33:F45) -> 0

Sheet Producto 4
B2: Producto
B4: Costo Unitario Total
B5: Concepto | C5: Costo Unitario Año Base | D5: Año 1 | E5: Año 2 | F5: Año 3 | G5: Año 4 | H5: Año 5
B6: Materia Prima e Insumos
B10: Total | C10: =SUM(C6:C9) -> 0 | D10: =SUM(D6:D9) -> 0 | E10: =SUM(E6:E9) -> 0 | F10: =SUM(F6:F9) -> 0 | G10: =SUM(G6:G9) -> 0 | H10: =SUM(H6:H9) -> 0
B13: Insumos
B14: Materia Prima | C14: Unidad de Medida | D14: Valor Unitario | E14: Cantidad Por unidad | F14: Total Costo Unitario
F15: =D15*E15 -> 0
F16: =D16*E16 -> 0
B28: Sub Total | D28: =SUM(D15:D27) -> 0 | F28: =SUM(F15:F27) -> 0
B31: Mano de Obra
B32: Mano de Obra | C32: Unidad de Medida | D32: Valor Unitario | E32: Cantidad Por unidad | F32: Total Costo Unitario
B46: Sub Total | D46: =SUM(D33:D45) -> 0 | F46: =SUM(F33:F45) -> 0

Sheet Comportamiento de Ventas
B2: Unidades a Producir | E2: Calificación de Comportamiento | F2: Calificación
B3: Producto | C3: Unidades en el Año | E3: Muy Alto | F3: 9
B4: ='Estructura de Mercado'!B8 -> Asistnte | C4: ='Estructura de Mercado'!G8 -> 12 | E4: Alto | F4: 7
E5: Normal | F5: 5
E6: Bajo | F6: 3
E7: Sin Ventas | F7: 0
B9: Total | C9: =SUM(C4:C8) -> 12 | E9: Ventas Anuales | F9: ='Datos Economicos'!F6 -> 44000000
B12: Meses | C12: Calificación | D12: Año 1
D13: Unidades | E13: Ventas
B14: Enero | C14: 3 | D14: =IF($C$26>0,(C14/$C$26)*$C$9,0) -> 0.69230769 | E14: =IF($D$26>0,($F$9*D14)/$D$26,) -> 2538461.5
B15: Febrero | C15: 5 | D15: =IF($C$26>0,(C15/$C$26)*$C$9,0) -> 1.1538462 | E15: =IF($D$26>0,($F$9*D15)/$D$26,) -> 4230769.2
B16: Marzo | C16: 5 | D16: =IF($C$26>0,(C16/$C$26)*$C$9,0) -> 1.1538462 | E16: =IF($D$26>0,($F$9*D16)/$D$26,) -> 4230769.2
B17: Abril | C17: 5 | D17: =IF($C$26>0,(C17/$C$26)*$C$9,0) -> 1.1538462 | E17: =IF($D$26>0,($F$9*D17)/$D$26,) -> 4230769.2
B18: Mayo | C18: 5 | D18: =IF($C$26>0,(C18/$C$26)*$C$9,0) -> 1.1538462 | E18: =IF($D$26>0,($F$9*D18)/$D$26,) -> 4230769.2
B19: Junio | C19: 3 | D19: =IF($C$26>0,(C19/$C$26)*$C$9,0) -> 0.69230769 | E19: =IF($D$26>0,($F$9*D19)/$D$26,) -> 2538461.5
B20: Julio | C20: 3 | D20: =IF($C$26>0,(C20/$C$26)*$C$9,0) -> 0.69230769 | E20: =IF($D$26>0,($F$9*D20)/$D$26,) -> 2538461.5
B21: Agosto | C21: 5 | D21: =IF($C$26>0,(C21/$C$26)*$C$9,0) -> 1.1538462 | E21: =IF($D$26>0,($F$9*D21)/$D$26,) -> 4230769.2
B22: Septiembre | C22: 5 | D22: =IF($C$26>0,(C22/$C$26)*$C$9,0) -> 1.1538462 | E22: =IF($D$26>0,($F$9*D22)/$D$26,) -> 4230769.2
B23: Octubre | C23: 5 | D23: =IF($C$26>0,(C23/$C$26)*$C$9,0) -> 1.1538462 | E23: =IF($D$26>0,($F$9*D23)/$D$26,) -> 4230769.2
B24: Noviembre | C24: 5 | D24: =IF($C$26>0,(C24/$C$26)*$C$9,0) -> 1.1538462 | E24: =IF($D$26>0,($F$9*D24)/$D$26,) -> 4230769.2
B25: Diciembre | C25: 3 | D25: =IF($C$26>0,(C25/$C$26)*$C$9,0) -> 0.69230769 | E25: =IF($D$26>0,($F$9*D25)/$D$26,) -> 2538461.5
B26: Total | C26: =SUM(C14:C25) -> 52 | D26: =SUM(D14:D25) -> 12 | E26: =SUM(E14:E25) -> 44000000

Sheet Comportamiento de Compras
B2: Unidades a Producir | E2: Calificación de Comportamiento | F2: Calificación | H2: Producto | I2: Total Costos
B3: Producto | C3: Unidades en el Año | E3: Muy Alto | F3: 9 | H3: ='Producto 1'!C2:H2 -> 0 | I3: ='Producto 1'!C10 -> 0
B4: ='Estructura de Mercado'!B8 -> Asistnte | C4: ='Estructura de Mercado'!G8 -> 12 | E4: Alto | F4: 7 | H4: ='Producto 2'!C2:H2 -> 0 | I4: ='Producto 2'!C10 -> 0
E5: Normal | F5: 5 | H5: ='Producto 3'!C2:H2 -> 0 | I5: ='Producto 3'!C10 -> 0
E6: Bajo | F6: 3 | H6: ='Producto 4'!C2:H2 -> 0 | I6: ='Producto 4'!C10 -> 0
E7: Sin Ventas | F7: 0
B9: Total | C9: =SUM(C4:C8) -> 12 | E9: Costos Anuales | F9: =SUM(I3:I6) -> 0
B12: Meses | C12: Calificación | D12: Año 1
D13: Unidades | E13: Ventas
B14: Enero | C14: 3 | D14: =IF($C$26>0,(C14/$C$26)*$C$9,0) -> 0.64285714 | E14: =IF($D$26>0,($F$9*D14)/$D$26,) -> 0
B15: Febrero | C15: 3 | D15: =IF($C$26>0,(C15/$C$26)*$C$9,0) -> 0.64285714 | E15: =IF($D$26>0,($F$9*D15)/$D$26,) -> 0
B16: Marzo | C16: 5 | D16: =IF($C$26>0,(C16/$C$26)*$C$9,0) -> 1.0714286 | E16: =IF($D$26>0,($F$9*D16)/$D$26,) -> 0
B17: Abril | C17: 5 | D17: =IF($C$26>0,(C17/$C$26)*$C$9,0) -> 1.0714286 | E17: =IF($D$26>0,($F$9*D17)/$D$26,) -> 0
B18: Mayo | C18: 5 | D18: =IF($C$26>0,(C18/$C$26)*$C$9,0) -> 1.0714286 | E18: =IF($D$26>0,($F$9*D18)/$D$26,) -> 0
B19: Junio | C19: 5 | D19: =IF($C$26>0,(C19/$C$26)*$C$9,0) -> 1.0714286 | E19: =IF($D$26>0,($F$9*D19)/$D$26,) -> 0
B20: Julio | C20: 5 | D20: =IF($C$26>0,(C20/$C$26)*$C$9,0) -> 1.0714286 | E20: =IF($D$26>0,($F$9*D20)/$D$26,) -> 0
B21: Agosto | C21: 5 | D21: =IF($C$26>0,(C21/$C$26)*$C$9,0) -> 1.0714286 | E21: =IF($D$26>0,($F$9*D21)/$D$26,) -> 0
B22: Septiembre | C22: 5 | D22: =IF($C$26>0,(C22/$C$26)*$C$9,0) -> 1.0714286 | E22: =IF($D$26>0,($F$9*D22)/$D$26,) -> 0
B23: Octubre | C23: 5 | D23: =IF($C$26>0,(C23/$C$26)*$C$9,0) -> 1.0714286 | E23: =IF($D$26>0,($F$9*D23)/$D$26,) -> 0
B24: Noviembre | C24: 5 | D24: =IF($C$26>0,(C24/$C$26)*$C$9,0) -> 1.0714286 | E24: =IF($D$26>0,($F$9*D24)/$D$26,) -> 0
B25: Diciembre | C25: 5 | D25: =IF($C$26>0,(C25/$C$26)*$C$9,0) -> 1.0714286 | E25: =IF($D$26>0,($F$9*D25)/$D$26,) -> 0
B26: Total | C26: =SUM(C14:C25) -> 56 | D26: =SUM(D14:D25) -> 12 | E26: =SUM(E14:E25) -> 0

Sheet Costos del Proyecto
C4: Costo Inicial del Proyecto
C5: Concepto | D5: Valor
C6: Gastos de Constitucion | D6: =SUM('Gastos de Constitución'!E11+'Gastos de Constitución'!E21) -> 0
C7: Plan de Inversión | D7: ='Plan de Inversion'!I8 -> 8020232
C8: Gastos de Personal | D8: ='Gastos de Personal'!C17 -> 7000000
C9: Parafiscales | D9: ='Gastos de Personal'!C36 -> 3593100
C10: Gastos Administrativos | D10: ='Gastos Administrativos'!D16 -> 1340000
C11: Gastos de Marketing | D11: ='Gastos de Marketing'!D16 -> 0
C12: Costos de Insumos | D12: ='Comportamiento de Compras'!F9 -> 0
C13: Total | D13: =SUM(D6:D12) -> 19953332
